Workbook

Sheet QUAN_LY_HO_SO
A1: A
A2: STT | B2: Tên nhiệm vụ / Cụm / Chuỗi | C2: Lĩnh vực | D2: Loại hình nhiệm vụ | E2: Hình thức triển khai 1 | F2: Hình thức triển khai 2 | G2: Hình thức xét | H2: Tên tổ chức chủ trì | I2: Địa chỉ tổ chức | J2: Điện thoại tổ chức | K2: Người đại diện pháp luật | L2: Chức vụ người đại diện | M2: Tài liệu chứng minh tư cách pháp lý (Nền tảng số) | N2: Thông tin về tổ chức đề xuất (Nền tảng số) | O2: Phân loại Chủ nhiệm | P2: Họ tên Chủ nhiệm | Q2: Học hàm, học vị | R2: Đơn vị công tác | S2: Email Chủ nhiệm | T2: Điện thoại Chủ nhiệm | U2: Lý lịch cá nhân (Nền tảng số) | V2: Tổng kinh phí đề xuất (VNĐ) | W2: Tỷ lệ NSNN (%) | X2: Kinh phí NSNN (VNĐ) | Y2: Tỷ lệ Ngoài NSNN (%) | Z2: Kinh phí Ngoài NSNN (VNĐ) | AA2: Thời gian thực hiện (Tháng) | AB2: Thời gian bắt đầu | AC2: Số lần gia hạn hợp đồng | AF2: Thời gian kết thúc | AG2: Trạng thái hồ sơ | AH2: Tổ chức phối hợp, đồng tài trợ | AI2: Nội dung cam kết phối hợp/đồng tài trợ | AJ2: Trạng thái hồ sơ
A3: 1 | B3: Nghiên cứu ứng dụng AI trong dự báo thời tiết | C3: Khoa học kỹ thuật và công nghệ | D3: Phát triển công nghệ | E3: Nhiệm vụ | F3: Thực hiện theo hình thức liên kết | G3: Đặt hàng | H3: Viện Công nghệ Thông tin | I3: 123 Đường ABC, Đà Nẵng | J3: 02363123456 | K3: Nguyễn Văn A | L3: Viện trưởng | M3: Đã cập nhật | N3: Đã cập nhật | O3: Nhà khoa học trẻ tài năng | P3: Trần Văn B | Q3: Giáo sư | R3: Khoa CNTT | S3: tranvanb@iti.vd | T3: 0905123456 | U3: Đã cập nhật | V3: 500000000 | W3: =X3/V3 -> 0.4 | X3: 200000000 | Y3: =100%-W3 -> 0.6 | Z3: =V3-X3 -> 300000000 | AA3: 24 | AG3: Đang xét
A4: 2 | B4: Số hóa và bảo tồn di sản văn hóa làng cổ Lộc Yên | C4: Công nghệ chiến lược | D4: Nghiên cứu ứng dụng | E4: Cụm nhiệm vụ | F4: Thực hiện theo hình thức hợp tác công tư | G4: Tài trợ | H4: Trường Đại học Bách khoa | I4: 456 Đường XYZ, Đà Nẵng | J4: 02363654321 | K4: Lê Thị C | L4: Hiệu trưởng | M4: Đã cập nhật | N4: Chưa cập nhật | O4: Không thuộc hai trường hợp trên | P4: Phạm Văn D | Q4: Thạc sĩ | R4: Khoa Kiến trúc | S4: phamvand@dut.udn.vn | T4: 0914987654 | U4: Đã cập nhật | V4: 300000000 | W4: =X4/V4 -> 0.33333333 | X4: 100000000 | Y4: =100%-W4 -> 0.66666667 | Z4: =V4-X4 -> 200000000 | AA4: 12 | AG4: Đang thực hiện
A5: 3 | B5: Số hóa và bảo tồn di sản văn hóa làng cổ Lộc Yên | C5: Khoa học xã hội | D5: Phát triển giải pháp xã hội | E5: Chuỗi nhiệm vụ | F5: Không thuộc 02 trường hợp trên | G5: Tài trợ | H5: Trường Đại học Bách khoa | I5: 456 Đường XYZ, Đà Nẵng | J5: 02363654321 | K5: Lê Thị C | L5: Hiệu trưởng | M5: Đã cập nhật | N5: Chưa cập nhật | O5: Không thuộc hai trường hợp trên | P5: Phạm Văn D | Q5: Cử nhân | R5: Khoa Kiến trúc | S5: phamvand@dut.udn.vn | T5: 0914987654 | U5: Chưa cập nhật | V5: 500000000 | W5: =X5/V5 -> 0.6 | X5: 300000000 | Y5: =100%-W5 -> 0.4 | Z5: =V5-X5 -> 200000000 | AA5: 12 | AG5: Đang xét
A6: 4 | B6: Công trình dự án khuyến nông | C6: Khoa học nông nghiệp | D6: Nghiên cứu ứng dụng | E6: Nhiệm vụ | F6: Thực hiện theo hình thức hợp tác công tư | G6: Đặt hàng | H6: Trung tâm khuyến nông | I6: Thành phố Hà Tĩnh | J6: 326598754 | K6: Nguyễn Thị N | L6: Phó Giám đốc | M6: Đã cập nhật | N6: Đã cập nhật | O6: Nhân tài về khoa học, công nghệ và đổi mới sáng tạo | P6: Nguyễn Hồ M | Q6: Phó Giáo sư | R6: Cục B | T6: 0326523545 | U6: Đã cập nhật | V6: 1000000000 | W6: =X6/V6 -> 0.8 | X6: 800000000 | Y6: =100%-W6 -> 0.2 | Z6: =V6-X6 -> 200000000 | AA6: 18 | AG6: Đang thực hiện
A7: 5 | B7: Nghiên cứu về loài B | C7: Khoa học nông nghiệp | D7: Phát triển giải pháp xã hội | E7: Nhiệm vụ | F7: Thực hiện theo hình thức liên kết | G7: Đặt hàng | H7: Viện nghiên cứu đại học | I7: Hà Tĩnh | J7: 123 | K7: Nguyễn Văn A | L7: Giám đốc | M7: Đã cập nhật | N7: Đã cập nhật | O7: Nhân tài về khoa học, công nghệ và đổi mới sáng tạo | P7: NGuyễn Văn B | Q7: Giáo sư | R7: Viện nghiên cứu đại học | T7: 35678 | U7: Đã cập nhật | V7: 1200000000 | W7: =X7/V7 -> 0.5 | X7: 600000000 | Y7: =100%-W7 -> 0.5 | Z7: =V7-X7 -> 600000000 | AA7: 12 | AG7: Đang xét
A8: 6 | B8: Nghiên cứu về đại học | C8: Khoa học tự nhiên | D8: Nghiên cứu cơ bản | E8: Nhiệm vụ | F8: Thực hiện theo hình thức liên kết | G8: Đặt hàng | H8: Viện nghiên cứu Đại học | I8: Thành phố Hà Tĩnh | J8: 098765432 | K8: Nguyễn Văn A | L8: Giám đốc | M8: Đã cập nhật | N8: Đã cập nhật | O8: Nhân tài về khoa học, công nghệ và đổi mới sáng tạo | P8: Nguyễn Văn B | Q8: Giáo sư | R8: Viện nghiên cứu Đại học | S8: a@gmail.com | T8: 0325698547 | U8: Đã cập nhật | V8: 1200000000 | W8: =X8/V8 -> 0.5 | X8: 600000000 | Y8: =100%-W8 -> 0.5 | Z8: =V8-X8 -> 600000000 | AA8: 24 | AG8: Đang xét
A9: 7 | B9: Ứng dụng công nghệ trong nghiên cứu | C9: Khoa học kỹ thuật và công nghệ | D9: Phát triển công nghệ | E9: Chuỗi nhiệm vụ | F9: Thực hiện theo hình thức liên kết | G9: Tài trợ | H9: Trung tâm ứng dụng chuyển giao công nghệ | I9: Hà Nội | J9: 325698541 | K9: Hồ Văn C | L9: Phó Giám đốc | M9: Đã cập nhật | N9: Đã cập nhật | O9: Nhà khoa học trẻ tài năng, kỹ sư trẻ tài năng | P9: Hồ Thế A | Q9: Phó Giáo sư | R9: Trung tâm ứng dụng chuyển giao Công nghệ | T9: 0326521458 | U9: Đã cập nhật | V9: 1500000000 | W9: =X9/V9 -> 0.8 | X9: 1200000000 | Y9: =100%-W9 -> 0.2 | Z9: =V9-X9 -> 300000000 | AA9: 24 | AG9: Đang thực hiện
A10: 8 | B10: Nghiên cứu ứng dụng AI | C10: Khoa học kỹ thuật và công nghệ | D10: Nghiên cứu ứng dụng | E10: Nhiệm vụ | F10: Không thuộc 02 trường hợp trên | G10: Đặt hàng | H10: Sở Tài nguyên và Môi trường | I10: Thành phố Hà Tĩnh | K10: Phan Văn A | L10: Phan Văn A | M10: Đã cập nhật | N10: Đã cập nhật | O10: Không thuộc hai trường hợp trên | P10: Lê Văn C | Q10: Thạc sĩ | R10: Sở Tài nguyên và Môi trường | T10: 0326598457 | U10: Đã cập nhật | V10: 600000000 | W10: 0.66666667 | X10: 400000000 | Y10: 0.33333333 | Z10: 200000000 | AA10: 36 | AG10: Đang xét

Sheet BAO_CAO_TONG_HOP
A1: BÁO CÁO TỔNG HỢP HỒ SƠ ĐĂNG KÝ CHỦ TRÌ NHIỆM VỤ KH&CN
A3: I. TỔNG QUAN HỒ SƠ & KINH PHÍ
A4: 1. Tổng số hồ sơ tiếp nhận | B4: =COUNTA(QUAN_LY_HO_SO!A3:A500) -> 8
A5: 2. Tổng kinh phí đề xuất | B5: =SUM(QUAN_LY_HO_SO!V3:V500) -> 6800000000
A6: 3. Tổng kinh phí Ngân sách nhà nước | B6: =SUM(QUAN_LY_HO_SO!X3:X500) -> 4200000000
A7: 4. Tổng kinh phí Ngoài ngân sách nhà nước | B7: =SUM(QUAN_LY_HO_SO!Z3:Z500) -> 2600000000
A9: II. THỐNG KÊ THEO LĨNH VỰC NGHIÊN CỨU | D9: TỔNG KINH PHÍ | E9: KINH PHÍ NSNN TƯƠNG ỨNG | F9: KINH PHÍ NGOÀI NSNN TƯƠNG ỨNG
A10: 1. Khoa học tự nhiên | B10: =COUNTIF(QUAN_LY_HO_SO!$C$3:$C$500, "Khoa học tự nhiên") -> 1 | D10: =SUMIF(QUAN_LY_HO_SO!$C$3:$C$504, "Khoa học tự nhiên", QUAN_LY_HO_SO!$V$3:$V$504) -> 1200000000 | E10: =SUMIF(QUAN_LY_HO_SO!$C$3:$C$504, "Khoa học tự nhiên", QUAN_LY_HO_SO!$X$3:$X$504) -> 600000000 | F10: =SUMIF(QUAN_LY_HO_SO!$C$3:$C$504, "Khoa học tự nhiên", QUAN_LY_HO_SO!$Z$3:$Z$504) -> 600000000
A11: 2. Khoa học kỹ thuật và công nghệ | B11: =COUNTIF(QUAN_LY_HO_SO!$C$3:$C$500, "Khoa học kỹ thuật và công nghệ") -> 3 | D11: =SUMIF(QUAN_LY_HO_SO!$C$3:$C$504, "Khoa học kỹ thuật và công nghệ", QUAN_LY_HO_SO!$V$3:$V$504) -> 2600000000 | E11: =SUMIF(QUAN_LY_HO_SO!$C$3:$C$504, "Khoa học kỹ thuật và công nghệ", QUAN_LY_HO_SO!$X$3:$X$504) -> 1800000000 | F11: =SUMIF(QUAN_LY_HO_SO!$C$3:$C$504, "Khoa học kỹ thuật và công nghệ", QUAN_LY_HO_SO!$Z$3:$Z$504) -> 800000000
A12: 3. Khoa học y, dược | B12: =COUNTIF(QUAN_LY_HO_SO!$C$3:$C$500, "Khoa học y, dược") -> 0 | D12: =SUMIF(QUAN_LY_HO_SO!$C$3:$C$504, "Khoa học y, dược", QUAN_LY_HO_SO!$V$3:$V$504) -> 0 | E12: =SUMIF(QUAN_LY_HO_SO!$C$3:$C$504, "Khoa học y, dược", QUAN_LY_HO_SO!$X$3:$X$504) -> 0 | F12: =SUMIF(QUAN_LY_HO_SO!$C$3:$C$504, "Khoa học y, dược", QUAN_LY_HO_SO!$Z$3:$Z$504) -> 0
A13: 4. Khoa học nông nghiệp | B13: =COUNTIF(QUAN_LY_HO_SO!$C$3:$C$500, "Khoa học nông nghiệp") -> 2 | D13: =SUMIF(QUAN_LY_HO_SO!$C$3:$C$504, "Khoa học nông nghiệp", QUAN_LY_HO_SO!$V$3:$V$504) -> 2200000000 | E13: =SUMIF(QUAN_LY_HO_SO!$C$3:$C$504, "Khoa học nông nghiệp", QUAN_LY_HO_SO!$X$3:$X$504) -> 1400000000 | F13: =SUMIF(QUAN_LY_HO_SO!$C$3:$C$504, "Khoa học nông nghiệp", QUAN_LY_HO_SO!$Z$3:$Z$504) -> 800000000
A14: 5. Khoa học xã hội | B14: =COUNTIF(QUAN_LY_HO_SO!$C$3:$C$500, "Khoa học xã hội") -> 1 | D14: =SUMIF(QUAN_LY_HO_SO!$C$3:$C$504, "Khoa học xã hội", QUAN_LY_HO_SO!$V$3:$V$504) -> 500000000 | E14: =SUMIF(QUAN_LY_HO_SO!$C$3:$C$504, "Khoa học xã hội", QUAN_LY_HO_SO!$X$3:$X$504) -> 300000000 | F14: =SUMIF(QUAN_LY_HO_SO!$C$3:$C$504, "Khoa học xã hội", QUAN_LY_HO_SO!$Z$3:$Z$504) -> 200000000
A15: 6. Khoa học nhân văn | B15: =COUNTIF(QUAN_LY_HO_SO!$C$3:$C$500, "Khoa học nhân văn") -> 0 | D15: =SUMIF(QUAN_LY_HO_SO!$C$3:$C$504, "Khoa học nhân văn", QUAN_LY_HO_SO!$V$3:$V$504) -> 0 | E15: =SUMIF(QUAN_LY_HO_SO!$C$3:$C$504, "Khoa học nhân văn", QUAN_LY_HO_SO!$X$3:$X$504) -> 0 | F15: =SUMIF(QUAN_LY_HO_SO!$C$3:$C$504, "Khoa học nhân văn", QUAN_LY_HO_SO!$Z$3:$Z$504) -> 0
A16: 7. Công nghệ chiến lược | B16: =COUNTIF(QUAN_LY_HO_SO!$C$3:$C$500, "Công nghệ chiến lược") -> 1 | D16: =SUMIF(QUAN_LY_HO_SO!$C$3:$C$504, "Công nghệ chiến lược", QUAN_LY_HO_SO!$V$3:$V$504) -> 300000000 | E16: =SUMIF(QUAN_LY_HO_SO!$C$3:$C$504, "Công nghệ chiến lược", QUAN_LY_HO_SO!$X$3:$X$504) -> 100000000 | F16: =SUMIF(QUAN_LY_HO_SO!$C$3:$C$504, "Công nghệ chiến lược", QUAN_LY_HO_SO!$Z$3:$Z$504) -> 200000000
A18: III. THỐNG KÊ THEO LOẠI HÌNH NHIỆM VỤ | D18: TỔNG KINH PHÍ | E18: KINH PHÍ NSNN TƯƠNG ỨNG | F18: KINH PHÍ NGOÀI NSNN TƯƠNG ỨNG
A19: 1. Nghiên cứu cơ bản | B19: =COUNTIF(QUAN_LY_HO_SO!$D$3:$D$508, "Nghiên cứu cơ bản") -> 1 | D19: =SUMIF(QUAN_LY_HO_SO!$D$3:$D$504, "Nghiên Cứu cơ bản", QUAN_LY_HO_SO!$V$3:$V$504) -> 1200000000 | E19: =SUMIF(QUAN_LY_HO_SO!$D$3:$D$504, "Nghiên Cứu cơ bản", QUAN_LY_HO_SO!$X$3:$X$504) -> 600000000 | F19: =SUMIF(QUAN_LY_HO_SO!$D$3:$D$504, "Nghiên Cứu cơ bản", QUAN_LY_HO_SO!$Z$3:$Z$504) -> 600000000
A20: 2. Nghiên cứu ứng dụng | B20: =COUNTIF(QUAN_LY_HO_SO!$D$3:$D$509, "Nghiên cứu ứng dụng") -> 3 | D20: =SUMIF(QUAN_LY_HO_SO!$D$3:$D$504, "Nghiên cứu ứng dụng", QUAN_LY_HO_SO!$V$3:$V$504) -> 1900000000 | E20: =SUMIF(QUAN_LY_HO_SO!$D$3:$D$504, "Nghiên cứu ứng dụng", QUAN_LY_HO_SO!$X$3:$X$504) -> 1300000000 | F20: =SUMIF(QUAN_LY_HO_SO!$D$3:$D$504, "Nghiên cứu ứng dụng", QUAN_LY_HO_SO!$Z$3:$Z$504) -> 600000000
A21: 3. Phát triển công nghệ | B21: =COUNTIF(QUAN_LY_HO_SO!$D$3:$D$510, "Phát triển công nghệ") -> 2 | D21: =SUMIF(QUAN_LY_HO_SO!$D$3:$D$504, "Phát triển công nghệ", QUAN_LY_HO_SO!$V$3:$V$504) -> 2000000000 | E21: =SUMIF(QUAN_LY_HO_SO!$D$3:$D$504, "Phát triển công nghệ", QUAN_LY_HO_SO!$X$3:$X$504) -> 1400000000 | F21: =SUMIF(QUAN_LY_HO_SO!$D$3:$D$504, "Phát triển công nghệ", QUAN_LY_HO_SO!$Z$3:$Z$504) -> 600000000
A22: 4. Phát triển giải pháp xã hội | B22: =COUNTIF(QUAN_LY_HO_SO!$D$3:$D$511, "Phát triển giải pháp xã hội") -> 1 | D22: =SUMIF(QUAN_LY_HO_SO!$D$3:$D$504, "Phát triển giải pháp xã hội", QUAN_LY_HO_SO!$V$3:$V$504) -> 500000000 | E22: =SUMIF(QUAN_LY_HO_SO!$D$3:$D$504, "Phát triển giải pháp xã hội", QUAN_LY_HO_SO!$X$3:$X$504) -> 300000000 | F22: =SUMIF(QUAN_LY_HO_SO!$D$3:$D$504, "Phát triển giải pháp xã hội", QUAN_LY_HO_SO!$Z$3:$Z$504) -> 200000000
A24: IV. PHÂN LOẠI CHỦ NHIỆM NHIỆM VỤ
A25: 1. Nhân tài về KH, CN & ĐMST | B25: =COUNTIF(QUAN_LY_HO_SO!$O$3:$O$500, "*Nhân tài*") -> 3
A26: 2. Nhà khoa học trẻ / Kỹ sư trẻ tài năng | B26: =COUNTIF(QUAN_LY_HO_SO!$O$3:$O$500, "*trẻ tài năng*") -> 2
A27: 3. Đối tượng khác | B27: =COUNTIF(QUAN_LY_HO_SO!$O$3:$O$500, "Không thuộc hai trường hợp trên") -> 3
A29: V. TÌNH TRẠNG CẬP NHẬT NỀN TẢNG SỐ QUỐC GIA
A30: 1. Hồ sơ đã cập nhật hoàn thiện (Cả 3 mục) | B30: =COUNTIFS(QUAN_LY_HO_SO!$M$3:$M$500, "Đã cập nhật", QUAN_LY_HO_SO!$N$3:$N$500, "Đã cập nhật", QUAN_LY_HO_SO!$U$3:$U$500, "Đã cập nhật") -> 6
A31: 2. Hồ sơ chưa cập nhật đủ thông tin | B31: =COUNTA(QUAN_LY_HO_SO!$A$3:$A$500) - B30 -> 2
A33: VI. HÌNH THỨC TRIỂN KHAI 1
A34: 1. Nhiệm vụ | B34: =COUNTIF(QUAN_LY_HO_SO!$E$3:$E$508, "Nhiệm vụ") -> 5
A35: 2. Cụm nhiệm vụ | B35: =COUNTIF(QUAN_LY_HO_SO!$E$3:$E$508, "Cụm nhiệm vụ") -> 1
A36: 3. Chuỗi nhiệm vụ | B36: =COUNTIF(QUAN_LY_HO_SO!$E$3:$E$508, "Chuỗi nhiệm vụ") -> 2
A38: VII. HÌNH THỨC TRIỂN KHAI 2
A39: 1. Thực hiện theo hình thức liên kết | B39: =COUNTIF(QUAN_LY_HO_SO!$F$3:$F$508, "Thực hiện theo hình thức liên kết") -> 4
A40: 2. Thực hiện theo hình thức hợp tác công tư | B40: =COUNTIF(QUAN_LY_HO_SO!$F$3:$F$508, "Thực hiện theo hình thức hợp tác công tư") -> 2
A41: 3. Không thuộc 02 trường hợp trên | B41: =COUNTIF(QUAN_LY_HO_SO!$F$3:$F$508, "Không thuộc 02 trường hợp trên") -> 2
A43: VIII. HÌNH THỨC XÉT
A44: 1. Đặt hàng | B44: =COUNTIF(QUAN_LY_HO_SO!$G$3:$G$508, "Đặt hàng") -> 5
A45: 2. Tài trợ | B45: =COUNTIF(QUAN_LY_HO_SO!$G$3:$G$508, "Tài trợ") -> 3
A47: IX. TRÌNH ĐỘ CHỦ NHIỆM ĐỀ TÀI
A48: 1. Giáo sư | B48: =COUNTIF(QUAN_LY_HO_SO!$Q$3:$Q$508, "Giáo sư") -> 3
A49: 2. Phó Giáo sư | B49: =COUNTIF(QUAN_LY_HO_SO!$Q$3:$Q$508,"Phó Giáo sư") -> 2
...
